test_unexpected_exception_is_passed_through_with
test_unexpected_exception_is_passed_through_callable
test_expected_exception_is_silent_with
raises
USE_PYTEST
test_second_argument_should_be_callable_or_string
test_lack_of_exception_triggers_AssertionError_with
py
test_expected_exception_is_silent_callable
test_lack_of_exception_triggers_AssertionError_callable
pytestmark
